Workbook

Sheet RawData
A1: NanoTemper Technologies | B1: NanoTemper Technologies
A2: MO.Affinity Analysis v2.3 | B2: MO.Affinity Analysis v2.3
A4: Origin of exported data | B4: Origin of exported data
A5: Project Title:
A6: Comment:
A7: Project File Path:
A8: Analysis-Set Name: | B8: Analysis-Set #4
A9: Exported from: | B9: Dose-Response (Grouped)
A10: Exported on: | B10: 45621.565
A12: Analysis Settings | B12: Analysis Settings
A13: Type of Analysis: | B13: MST
A14: Evaluation strategy: | B14: On Time
A15: Cold Region Start: | B15: -1
A16: Cold Region End: | B16: 0
A17: Hot Region Start: | B17: 4
A18: Hot Region End: | B18: 5
A20: Sample Information | B20: Sample Information
A21: Merge-Set Name: | B21: Experiment 1 (#01)
A22: Date of Measurement: | B22: 2024-11-25 12:24:56.64 → 2024-11-25 13:18:03.103
A23: Capillary Type: | B23: Unspecified container/capillary type
A24: Target: | B24: CD1d
A25: TargetConcentration: | B25: 1e-07
A26: Ligand: | B26: DDM
A28: Measurement Settings | B28: Measurement Settings
A29: MST-Power: | B29: Medium
A30: Excitation-Power: | B30: 50
A31: Excitation type: | B31: Nano - RED
A32: Thermostat Setpoint: | B32: 25
A34: Fit Results (Kd) | B34: Fit Results (Kd)
A35: Fit Model: | B35: Kd
A36: Bound | B36: 874.65384
A37: Unbound | B37: 807.55033
A38: Kd | B38: 4.3519497e-05
A39: TargetConc | B39: 1e-07
A40: Standard Deviation: | B40: 11.02328
A41: Kd Confidence: | B41: 2.6448723e-05
A43: Dose Response Curve | B43: Dose Response Curve | C43: Dose Response Curve | E43: Shifted Dose Response Curve of CD1d_100_DDM (#03) | F43: Shifted Dose Response Curve of CD1d_100_DDM (#03) | H43: Shifted Dose Response Curve of CD1d_50_DDM (#02) | I43: Shifted Dose Response Curve of CD1d_50_DDM (#02) | K43: Shifted Dose Response Curve of CD1d_100_DDM (#01) | L43: Shifted Dose Response Curve of CD1d_100_DDM (#01)
A44: Ligand Concentration [M] | B44: Fnorm [‰] | C44: Error Value | E44: Ligand Concentration [M] | F44: Fnorm [‰] | H44: Ligand Concentration [M] | I44: Fnorm [‰] | K44: Ligand Concentration [M] | L44: Fnorm [‰]
A45: 0.001 | B45: 864.08654 | C45: 34.963865 | E45: 0.001 | F45: 845.52563 | H45: 0.001 | I45: 904.41681 | K45: 0.001 | L45: 842.31718
A46: 0.0005 | B46: 867.17922 | C46: 28.271209 | E46: 0.0005 | F46: 856.90817 | H46: 0.0005 | I46: 845.47932 | K46: 0.0005 | L46: 899.15018
...

Sheet Graph

Sheet Fit-Values
A1: Dose | B1: FNorm
A2: 0.00095043948 | B2: =((RawData!B36-RawData!B37)*(RawData!B39+A2+RawData!B38-SQRT(POWER(RawData!B39+A2+RawData!B38,2)-(4*RawData!B39*A2)))/(2*RawData!B39))+RawData!B37 -> 871.71549
A3: 0.0009033352 | B3: =((RawData!B36-RawData!B37)*(RawData!B39+A3+RawData!B38-SQRT(POWER(RawData!B39+A3+RawData!B38,2)-(4*RawData!B39*A3)))/(2*RawData!B39))+RawData!B37 -> 871.5693
A4: 0.00085856544 | B4: =((RawData!B36-RawData!B37)*(RawData!B39+A4+RawData!B38-SQRT(POWER(RawData!B39+A4+RawData!B38,2)-(4*RawData!B39*A4)))/(2*RawData!B39))+RawData!B37 -> 871.4162
A5: 0.00081601448 | B5: =((RawData!B36-RawData!B37)*(RawData!B39+A5+RawData!B38-SQRT(POWER(RawData!B39+A5+RawData!B38,2)-(4*RawData!B39*A5)))/(2*RawData!B39))+RawData!B37 -> 871.25591
A6: 0.00077557238 | B6: =((RawData!B36-RawData!B37)*(RawData!B39+A6+RawData!B38-SQRT(POWER(RawData!B39+A6+RawData!B38,2)-(4*RawData!B39*A6)))/(2*RawData!B39))+RawData!B37 -> 871.08812
A7: 0.00073713461 | B7: =((RawData!B36-RawData!B37)*(RawData!B39+A7+RawData!B38-SQRT(POWER(RawData!B39+A7+RawData!B38,2)-(4*RawData!B39*A7)))/(2*RawData!B39))+RawData!B37 -> 870.91253
A8: 0.00070060183 | B8: =((RawData!B36-RawData!B37)*(RawData!B39+A8+RawData!B38-SQRT(POWER(RawData!B39+A8+RawData!B38,2)-(4*RawData!B39*A8)))/(2*RawData!B39))+RawData!B37 -> 870.72883
A9: 0.00066587964 | B9: =((RawData!B36-RawData!B37)*(RawData!B39+A9+RawData!B38-SQRT(POWER(RawData!B39+A9+RawData!B38,2)-(4*RawData!B39*A9)))/(2*RawData!B39))+RawData!B37 -> 870.53669
A10: 0.0006328783 | B10: =((RawData!B36-RawData!B37)*(RawData!B39+A10+RawData!B38-SQRT(POWER(RawData!B39+A10+RawData!B38,2)-(4*RawData!B39*A10)))/(2*RawData!B39))+RawData!B37 -> 870.33579
A11: 0.00060151252 | B11: =((RawData!B36-RawData!B37)*(RawData!B39+A11+RawData!B38-SQRT(POWER(RawData!B39+A11+RawData!B38,2)-(4*RawData!B39*A11)))/(2*RawData!B39))+RawData!B37 -> 870.12579
A12: 0.00057170124 | B12: =((RawData!B36-RawData!B37)*(RawData!B39+A12+RawData!B38-SQRT(POWER(RawData!B39+A12+RawData!B38,2)-(4*RawData!B39*A12)))/(2*RawData!B39))+RawData!B37 -> 869.90635
A13: 0.00054336743 | B13: =((RawData!B36-RawData!B37)*(RawData!B39+A13+RawData!B38-SQRT(POWER(RawData!B39+A13+RawData!B38,2)-(4*RawData!B39*A13)))/(2*RawData!B39))+RawData!B37 -> 869.67712
A14: 0.00051643786 | B14: =((RawData!B36-RawData!B37)*(RawData!B39+A14+RawData!B38-SQRT(POWER(RawData!B39+A14+RawData!B38,2)-(4*RawData!B39*A14)))/(2*RawData!B39))+RawData!B37 -> 869.43774
A15: 0.00049084293 | B15: =((RawData!B36-RawData!B37)*(RawData!B39+A15+RawData!B38-SQRT(POWER(RawData!B39+A15+RawData!B38,2)-(4*RawData!B39*A15)))/(2*RawData!B39))+RawData!B37 -> 869.18786
A16: 0.0004665165 | B16: =((RawData!B36-RawData!B37)*(RawData!B39+A16+RawData!B38-SQRT(POWER(RawData!B39+A16+RawData!B38,2)-(4*RawData!B39*A16)))/(2*RawData!B39))+RawData!B37 -> 868.92711
A17: 0.00044339569 | B17: =((RawData!B36-RawData!B37)*(RawData!B39+A17+RawData!B38-SQRT(POWER(RawData!B39+A17+RawData!B38,2)-(4*RawData!B39*A17)))/(2*RawData!B39))+RawData!B37 -> 868.65514
A18: 0.00042142077 | B18: =((RawData!B36-RawData!B37)*(RawData!B39+A18+RawData!B38-SQRT(POWER(RawData!B39+A18+RawData!B38,2)-(4*RawData!B39*A18)))/(2*RawData!B39))+RawData!B37 -> 868.37157
A19: 0.00040053494 | B19: =((RawData!B36-RawData!B37)*(RawData!B39+A19+RawData!B38-SQRT(POWER(RawData!B39+A19+RawData!B38,2)-(4*RawData!B39*A19)))/(2*RawData!B39))+RawData!B37 -> 868.07603
A20: 0.00038068422 | B20: =((RawData!B36-RawData!B37)*(RawData!B39+A20+RawData!B38-SQRT(POWER(RawData!B39+A20+RawData!B38,2)-(4*RawData!B39*A20)))/(2*RawData!B39))+RawData!B37 -> 867.76816
A21: 0.00036181731 | B21: =((RawData!B36-RawData!B37)*(RawData!B39+A21+RawData!B38-SQRT(POWER(RawData!B39+A21+RawData!B38,2)-(4*RawData!B39*A21)))/(2*RawData!B39))+RawData!B37 -> 867.4476
A22: 0.00034388545 | B22: =((RawData!B36-RawData!B37)*(RawData!B39+A22+RawData!B38-SQRT(POWER(RawData!B39+A22+RawData!B38,2)-(4*RawData!B39*A22)))/(2*RawData!B39))+RawData!B37 -> 867.11397
A23: 0.00032684231 | B23: =((RawData!B36-RawData!B37)*(RawData!B39+A23+RawData!B38-SQRT(POWER(RawData!B39+A23+RawData!B38,2)-(4*RawData!B39*A23)))/(2*RawData!B39))+RawData!B37 -> 866.76693
A24: 0.00031064384 | B24: =((RawData!B36-RawData!B37)*(RawData!B39+A24+RawData!B38-SQRT(POWER(RawData!B39+A24+RawData!B38,2)-(4*RawData!B39*A24)))/(2*RawData!B39))+RawData!B37 -> 866.40613
A25: 0.00029524817 | B25: =((RawData!B36-RawData!B37)*(RawData!B39+A25+RawData!B38-SQRT(POWER(RawData!B39+A25+RawData!B38,2)-(4*RawData!B39*A25)))/(2*RawData!B39))+RawData!B37 -> 866.03122
A26: 0.00028061551 | B26: =((RawData!B36-RawData!B37)*(RawData!B39+A26+RawData!B38-SQRT(POWER(RawData!B39+A26+RawData!B38,2)-(4*RawData!B39*A26)))/(2*RawData!B39))+RawData!B37 -> 865.64188
A27: 0.00026670806 | B27: =((RawData!B36-RawData!B37)*(RawData!B39+A27+RawData!B38-SQRT(POWER(RawData!B39+A27+RawData!B38,2)-(4*RawData!B39*A27)))/(2*RawData!B39))+RawData!B37 -> 865.23778
A28: 0.00025348987 | B28: =((RawData!B36-RawData!B37)*(RawData!B39+A28+RawData!B38-SQRT(POWER(RawData!B39+A28+RawData!B38,2)-(4*RawData!B39*A28)))/(2*RawData!B39))+RawData!B37 -> 864.81862
A29: 0.00024092678 | B29: =((RawData!B36-RawData!B37)*(RawData!B39+A29+RawData!B38-SQRT(POWER(RawData!B39+A29+RawData!B38,2)-(4*RawData!B39*A29)))/(2*RawData!B39))+RawData!B37 -> 864.38413
A30: 0.00022898632 | B30: =((RawData!B36-RawData!B37)*(RawData!B39+A30+RawData!B38-SQRT(POWER(RawData!B39+A30+RawData!B38,2)-(4*RawData!B39*A30)))/(2*RawData!B39))+RawData!B37 -> 863.93402
A31: 0.00021763764 | B31: =((RawData!B36-RawData!B37)*(RawData!B39+A31+RawData!B38-SQRT(POWER(RawData!B39+A31+RawData!B38,2)-(4*RawData!B39*A31)))/(2*RawData!B39))+RawData!B37 -> 863.46807
A32: 0.00020685141 | B32: =((RawData!B36-RawData!B37)*(RawData!B39+A32+RawData!B38-SQRT(POWER(RawData!B39+A32+RawData!B38,2)-(4*RawData!B39*A32)))/(2*RawData!B39))+RawData!B37 -> 862.98605
A33: 0.00019659974 | B33: =((RawData!B36-RawData!B37)*(RawData!B39+A33+RawData!B38-SQRT(POWER(RawData!B39+A33+RawData!B38,2)-(4*RawData!B39*A33)))/(2*RawData!B39))+RawData!B37 -> 862.48777
A34: 0.00018685616 | B34: =((RawData!B36-RawData!B37)*(RawData!B39+A34+RawData!B38-SQRT(POWER(RawData!B39+A34+RawData!B38,2)-(4*RawData!B39*A34)))/(2*RawData!B39))+RawData!B37 -> 861.97307
A35: 0.00017759547 | B35: =((RawData!B36-RawData!B37)*(RawData!B39+A35+RawData!B38-SQRT(POWER(RawData!B39+A35+RawData!B38,2)-(4*RawData!B39*A35)))/(2*RawData!B39))+RawData!B37 -> 861.44183
A36: 0.00016879374 | B36: =((RawData!B36-RawData!B37)*(RawData!B39+A36+RawData!B38-SQRT(POWER(RawData!B39+A36+RawData!B38,2)-(4*RawData!B39*A36)))/(2*RawData!B39))+RawData!B37 -> 860.89396
A37: 0.00016042824 | B37: =((RawData!B36-RawData!B37)*(RawData!B39+A37+RawData!B38-SQRT(POWER(RawData!B39+A37+RawData!B38,2)-(4*RawData!B39*A37)))/(2*RawData!B39))+RawData!B37 -> 860.32939
A38: 0.00015247733 | B38: =((RawData!B36-RawData!B37)*(RawData!B39+A38+RawData!B38-SQRT(POWER(RawData!B39+A38+RawData!B38,2)-(4*RawData!B39*A38)))/(2*RawData!B39))+RawData!B37 -> 859.74813
A39: 0.00014492047 | B39: =((RawData!B36-RawData!B37)*(RawData!B39+A39+RawData!B38-SQRT(POWER(RawData!B39+A39+RawData!B38,2)-(4*RawData!B39*A39)))/(2*RawData!B39))+RawData!B37 -> 859.15021
A40: 0.00013773814 | B40: =((RawData!B36-RawData!B37)*(RawData!B39+A40+RawData!B38-SQRT(POWER(RawData!B39+A40+RawData!B38,2)-(4*RawData!B39*A40)))/(2*RawData!B39))+RawData!B37 -> 858.5357
...
