Workbook

Sheet RawData
A1: NanoTemper Technologies | B1: NanoTemper Technologies
A2: MO.Affinity Analysis v2.3 | B2: MO.Affinity Analysis v2.3
A4: Origin of exported data | B4: Origin of exported data
A5: Project Title:
A6: Comment:
A7: Project File Path:
A8: Analysis-Set Name: | B8: Analysis-Set #1
A9: Exported from: | B9: Dose-Response (Grouped)
A10: Exported on: | B10: 45684.282
A12: Analysis Settings | B12: Analysis Settings
A13: Type of Analysis: | B13: MST
A14: Evaluation strategy: | B14: On Time
A15: Cold Region Start: | B15: -1
A16: Cold Region End: | B16: 0
A17: Hot Region Start: | B17: 4
A18: Hot Region End: | B18: 5
A20: Sample Information | B20: Sample Information
A21: Merge-Set Name: | B21: Experiment 1 (#01)
A22: Date of Measurement: | B22: 2025-01-22 10:35:06.196 → 2025-01-22 10:45:14.204
A23: Capillary Type: | B23: Unspecified container/capillary type
A24: Target: | B24: CD1d
A25: TargetConcentration: | B25: 5e-08
A26: Ligand: | B26: LPC
A28: Measurement Settings | B28: Measurement Settings
A29: MST-Power: | B29: Medium
A30: Excitation-Power: | B30: 50
A31: Excitation type: | B31: Nano - RED
A32: Thermostat Setpoint: | B32: 25
A34: Fit Results (Kd) | B34: Fit Results (Kd)
A35: Fit Model: | B35: Kd
A36: Bound | B36: 832.84724
A37: Unbound | B37: 797.22145
A38: Kd | B38: 7.9941068e-06
A39: TargetConc | B39: 5e-08
A40: Standard Deviation: | B40: 4.5005935
A41: Kd Confidence: | B41: 3.3365035e-06
A43: Fit Results (Hill) | B43: Fit Results (Hill)
A44: Fit Model: | B44: Hill
A45: Bound | B45: 828.79809
A46: Unbound | B46: 798.74966
...

Sheet Graph

Sheet Fit-Values
A1: Dose | B1: FNorm | C1: FNorm
A2: 0.0001866066 | B2: =((RawData!B36-RawData!B37)*(RawData!B39+A2+RawData!B38-SQRT(POWER(RawData!B39+A2+RawData!B38,2)-(4*RawData!B39*A2)))/(2*RawData!B39))+RawData!B37 -> 831.38339 | C2: =RawData!B46 + ((RawData!B45 - RawData!B46) * (1 / (1 + (POWER(RawData!B48 / A2, RawData!B47))))) -> 828.79807
A3: 0.00017411011 | B3: =((RawData!B36-RawData!B37)*(RawData!B39+A3+RawData!B38-SQRT(POWER(RawData!B39+A3+RawData!B38,2)-(4*RawData!B39*A3)))/(2*RawData!B39))+RawData!B37 -> 831.28291 | C3: =RawData!B46 + ((RawData!B45 - RawData!B46) * (1 / (1 + (POWER(RawData!B48 / A3, RawData!B47))))) -> 828.79806
A4: 0.00016245048 | B4: =((RawData!B36-RawData!B37)*(RawData!B39+A4+RawData!B38-SQRT(POWER(RawData!B39+A4+RawData!B38,2)-(4*RawData!B39*A4)))/(2*RawData!B39))+RawData!B37 -> 831.17587 | C4: =RawData!B46 + ((RawData!B45 - RawData!B46) * (1 / (1 + (POWER(RawData!B48 / A4, RawData!B47))))) -> 828.79805
A5: 0.00015157166 | B5: =((RawData!B36-RawData!B37)*(RawData!B39+A5+RawData!B38-SQRT(POWER(RawData!B39+A5+RawData!B38,2)-(4*RawData!B39*A5)))/(2*RawData!B39))+RawData!B37 -> 831.06189 | C5: =RawData!B46 + ((RawData!B45 - RawData!B46) * (1 / (1 + (POWER(RawData!B48 / A5, RawData!B47))))) -> 828.79803
A6: 0.00014142136 | B6: =((RawData!B36-RawData!B37)*(RawData!B39+A6+RawData!B38-SQRT(POWER(RawData!B39+A6+RawData!B38,2)-(4*RawData!B39*A6)))/(2*RawData!B39))+RawData!B37 -> 830.94057 | C6: =RawData!B46 + ((RawData!B45 - RawData!B46) * (1 / (1 + (POWER(RawData!B48 / A6, RawData!B47))))) -> 828.79801
A7: 0.00013195079 | B7: =((RawData!B36-RawData!B37)*(RawData!B39+A7+RawData!B38-SQRT(POWER(RawData!B39+A7+RawData!B38,2)-(4*RawData!B39*A7)))/(2*RawData!B39))+RawData!B37 -> 830.8115 | C7: =RawData!B46 + ((RawData!B45 - RawData!B46) * (1 / (1 + (POWER(RawData!B48 / A7, RawData!B47))))) -> 828.79798
A8: 0.00012311444 | B8: =((RawData!B36-RawData!B37)*(RawData!B39+A8+RawData!B38-SQRT(POWER(RawData!B39+A8+RawData!B38,2)-(4*RawData!B39*A8)))/(2*RawData!B39))+RawData!B37 -> 830.67425 | C8: =RawData!B46 + ((RawData!B45 - RawData!B46) * (1 / (1 + (POWER(RawData!B48 / A8, RawData!B47))))) -> 828.79794
A9: 0.00011486984 | B9: =((RawData!B36-RawData!B37)*(RawData!B39+A9+RawData!B38-SQRT(POWER(RawData!B39+A9+RawData!B38,2)-(4*RawData!B39*A9)))/(2*RawData!B39))+RawData!B37 -> 830.52838 | C9: =RawData!B46 + ((RawData!B45 - RawData!B46) * (1 / (1 + (POWER(RawData!B48 / A9, RawData!B47))))) -> 828.79789
A10: 0.00010717735 | B10: =((RawData!B36-RawData!B37)*(RawData!B39+A10+RawData!B38-SQRT(POWER(RawData!B39+A10+RawData!B38,2)-(4*RawData!B39*A10)))/(2*RawData!B39))+RawData!B37 -> 830.37344 | C10: =RawData!B46 + ((RawData!B45 - RawData!B46) * (1 / (1 + (POWER(RawData!B48 / A10, RawData!B47))))) -> 828.79782
A11: 0.0001 | B11: =((RawData!B36-RawData!B37)*(RawData!B39+A11+RawData!B38-SQRT(POWER(RawData!B39+A11+RawData!B38,2)-(4*RawData!B39*A11)))/(2*RawData!B39))+RawData!B37 -> 830.20897 | C11: =RawData!B46 + ((RawData!B45 - RawData!B46) * (1 / (1 + (POWER(RawData!B48 / A11, RawData!B47))))) -> 828.79773
A12: 9.33033e-05 | B12: =((RawData!B36-RawData!B37)*(RawData!B39+A12+RawData!B38-SQRT(POWER(RawData!B39+A12+RawData!B38,2)-(4*RawData!B39*A12)))/(2*RawData!B39))+RawData!B37 -> 830.03448 | C12: =RawData!B46 + ((RawData!B45 - RawData!B46) * (1 / (1 + (POWER(RawData!B48 / A12, RawData!B47))))) -> 828.7976
A13: 8.7055057e-05 | B13: =((RawData!B36-RawData!B37)*(RawData!B39+A13+RawData!B38-SQRT(POWER(RawData!B39+A13+RawData!B38,2)-(4*RawData!B39*A13)))/(2*RawData!B39))+RawData!B37 -> 829.84949 | C13: =RawData!B46 + ((RawData!B45 - RawData!B46) * (1 / (1 + (POWER(RawData!B48 / A13, RawData!B47))))) -> 828.79743
A14: 8.122524e-05 | B14: =((RawData!B36-RawData!B37)*(RawData!B39+A14+RawData!B38-SQRT(POWER(RawData!B39+A14+RawData!B38,2)-(4*RawData!B39*A14)))/(2*RawData!B39))+RawData!B37 -> 829.65352 | C14: =RawData!B46 + ((RawData!B45 - RawData!B46) * (1 / (1 + (POWER(RawData!B48 / A14, RawData!B47))))) -> 828.7972
A15: 7.5785829e-05 | B15: =((RawData!B36-RawData!B37)*(RawData!B39+A15+RawData!B38-SQRT(POWER(RawData!B39+A15+RawData!B38,2)-(4*RawData!B39*A15)))/(2*RawData!B39))+RawData!B37 -> 829.44607 | C15: =RawData!B46 + ((RawData!B45 - RawData!B46) * (1 / (1 + (POWER(RawData!B48 / A15, RawData!B47))))) -> 828.7969
A16: 7.0710679e-05 | B16: =((RawData!B36-RawData!B37)*(RawData!B39+A16+RawData!B38-SQRT(POWER(RawData!B39+A16+RawData!B38,2)-(4*RawData!B39*A16)))/(2*RawData!B39))+RawData!B37 -> 829.22664 | C16: =RawData!B46 + ((RawData!B45 - RawData!B46) * (1 / (1 + (POWER(RawData!B48 / A16, RawData!B47))))) -> 828.79649
A17: 6.5975396e-05 | B17: =((RawData!B36-RawData!B37)*(RawData!B39+A17+RawData!B38-SQRT(POWER(RawData!B39+A17+RawData!B38,2)-(4*RawData!B39*A17)))/(2*RawData!B39))+RawData!B37 -> 828.99474 | C17: =RawData!B46 + ((RawData!B45 - RawData!B46) * (1 / (1 + (POWER(RawData!B48 / A17, RawData!B47))))) -> 828.79594
A18: 6.1557221e-05 | B18: =((RawData!B36-RawData!B37)*(RawData!B39+A18+RawData!B38-SQRT(POWER(RawData!B39+A18+RawData!B38,2)-(4*RawData!B39*A18)))/(2*RawData!B39))+RawData!B37 -> 828.74987 | C18: =RawData!B46 + ((RawData!B45 - RawData!B46) * (1 / (1 + (POWER(RawData!B48 / A18, RawData!B47))))) -> 828.79519
A19: 5.7434918e-05 | B19: =((RawData!B36-RawData!B37)*(RawData!B39+A19+RawData!B38-SQRT(POWER(RawData!B39+A19+RawData!B38,2)-(4*RawData!B39*A19)))/(2*RawData!B39))+RawData!B37 -> 828.49157 | C19: =RawData!B46 + ((RawData!B45 - RawData!B46) * (1 / (1 + (POWER(RawData!B48 / A19, RawData!B47))))) -> 828.7942
A20: 5.3588674e-05 | B20: =((RawData!B36-RawData!B37)*(RawData!B39+A20+RawData!B38-SQRT(POWER(RawData!B39+A20+RawData!B38,2)-(4*RawData!B39*A20)))/(2*RawData!B39))+RawData!B37 -> 828.21936 | C20: =RawData!B46 + ((RawData!B45 - RawData!B46) * (1 / (1 + (POWER(RawData!B48 / A20, RawData!B47))))) -> 828.79286
A21: 5e-05 | B21: =((RawData!B36-RawData!B37)*(RawData!B39+A21+RawData!B38-SQRT(POWER(RawData!B39+A21+RawData!B38,2)-(4*RawData!B39*A21)))/(2*RawData!B39))+RawData!B37 -> 827.93281 | C21: =RawData!B46 + ((RawData!B45 - RawData!B46) * (1 / (1 + (POWER(RawData!B48 / A21, RawData!B47))))) -> 828.79106
A22: 4.665165e-05 | B22: =((RawData!B36-RawData!B37)*(RawData!B39+A22+RawData!B38-SQRT(POWER(RawData!B39+A22+RawData!B38,2)-(4*RawData!B39*A22)))/(2*RawData!B39))+RawData!B37 -> 827.63149 | C22: =RawData!B46 + ((RawData!B45 - RawData!B46) * (1 / (1 + (POWER(RawData!B48 / A22, RawData!B47))))) -> 828.78865
A23: 4.3527529e-05 | B23: =((RawData!B36-RawData!B37)*(RawData!B39+A23+RawData!B38-SQRT(POWER(RawData!B39+A23+RawData!B38,2)-(4*RawData!B39*A23)))/(2*RawData!B39))+RawData!B37 -> 827.315 | C23: =RawData!B46 + ((RawData!B45 - RawData!B46) * (1 / (1 + (POWER(RawData!B48 / A23, RawData!B47))))) -> 828.78541
A24: 4.061262e-05 | B24: =((RawData!B36-RawData!B37)*(RawData!B39+A24+RawData!B38-SQRT(POWER(RawData!B39+A24+RawData!B38,2)-(4*RawData!B39*A24)))/(2*RawData!B39))+RawData!B37 -> 826.98301 | C24: =RawData!B46 + ((RawData!B45 - RawData!B46) * (1 / (1 + (POWER(RawData!B48 / A24, RawData!B47))))) -> 828.78105
A25: 3.7892915e-05 | B25: =((RawData!B36-RawData!B37)*(RawData!B39+A25+RawData!B38-SQRT(POWER(RawData!B39+A25+RawData!B38,2)-(4*RawData!B39*A25)))/(2*RawData!B39))+RawData!B37 -> 826.63519 | C25: =RawData!B46 + ((RawData!B45 - RawData!B46) * (1 / (1 + (POWER(RawData!B48 / A25, RawData!B47))))) -> 828.77521
A26: 3.5355339e-05 | B26: =((RawData!B36-RawData!B37)*(RawData!B39+A26+RawData!B38-SQRT(POWER(RawData!B39+A26+RawData!B38,2)-(4*RawData!B39*A26)))/(2*RawData!B39))+RawData!B37 -> 826.27128 | C26: =RawData!B46 + ((RawData!B45 - RawData!B46) * (1 / (1 + (POWER(RawData!B48 / A26, RawData!B47))))) -> 828.76735
A27: 3.2987698e-05 | B27: =((RawData!B36-RawData!B37)*(RawData!B39+A27+RawData!B38-SQRT(POWER(RawData!B39+A27+RawData!B38,2)-(4*RawData!B39*A27)))/(2*RawData!B39))+RawData!B37 -> 825.89108 | C27: =RawData!B46 + ((RawData!B45 - RawData!B46) * (1 / (1 + (POWER(RawData!B48 / A27, RawData!B47))))) -> 828.75681
A28: 3.0778611e-05 | B28: =((RawData!B36-RawData!B37)*(RawData!B39+A28+RawData!B38-SQRT(POWER(RawData!B39+A28+RawData!B38,2)-(4*RawData!B39*A28)))/(2*RawData!B39))+RawData!B37 -> 825.49444 | C28: =RawData!B46 + ((RawData!B45 - RawData!B46) * (1 / (1 + (POWER(RawData!B48 / A28, RawData!B47))))) -> 828.74265
A29: 2.8717459e-05 | B29: =((RawData!B36-RawData!B37)*(RawData!B39+A29+RawData!B38-SQRT(POWER(RawData!B39+A29+RawData!B38,2)-(4*RawData!B39*A29)))/(2*RawData!B39))+RawData!B37 -> 825.0813 | C29: =RawData!B46 + ((RawData!B45 - RawData!B46) * (1 / (1 + (POWER(RawData!B48 / A29, RawData!B47))))) -> 828.72366
A30: 2.6794337e-05 | B30: =((RawData!B36-RawData!B37)*(RawData!B39+A30+RawData!B38-SQRT(POWER(RawData!B39+A30+RawData!B38,2)-(4*RawData!B39*A30)))/(2*RawData!B39))+RawData!B37 -> 824.65165 | C30: =RawData!B46 + ((RawData!B45 - RawData!B46) * (1 / (1 + (POWER(RawData!B48 / A30, RawData!B47))))) -> 828.69817
A31: 2.5e-05 | B31: =((RawData!B36-RawData!B37)*(RawData!B39+A31+RawData!B38-SQRT(POWER(RawData!B39+A31+RawData!B38,2)-(4*RawData!B39*A31)))/(2*RawData!B39))+RawData!B37 -> 824.20559 | C31: =RawData!B46 + ((RawData!B45 - RawData!B46) * (1 / (1 + (POWER(RawData!B48 / A31, RawData!B47))))) -> 828.664
A32: 2.3325825e-05 | B32: =((RawData!B36-RawData!B37)*(RawData!B39+A32+RawData!B38-SQRT(POWER(RawData!B39+A32+RawData!B38,2)-(4*RawData!B39*A32)))/(2*RawData!B39))+RawData!B37 -> 823.74329 | C32: =RawData!B46 + ((RawData!B45 - RawData!B46) * (1 / (1 + (POWER(RawData!B48 / A32, RawData!B47))))) -> 828.61822
A33: 2.1763764e-05 | B33: =((RawData!B36-RawData!B37)*(RawData!B39+A33+RawData!B38-SQRT(POWER(RawData!B39+A33+RawData!B38,2)-(4*RawData!B39*A33)))/(2*RawData!B39))+RawData!B37 -> 823.26502 | C33: =RawData!B46 + ((RawData!B45 - RawData!B46) * (1 / (1 + (POWER(RawData!B48 / A33, RawData!B47))))) -> 828.55693
A34: 2.030631e-05 | B34: =((RawData!B36-RawData!B37)*(RawData!B39+A34+RawData!B38-SQRT(POWER(RawData!B39+A34+RawData!B38,2)-(4*RawData!B39*A34)))/(2*RawData!B39))+RawData!B37 -> 822.77115 | C34: =RawData!B46 + ((RawData!B45 - RawData!B46) * (1 / (1 + (POWER(RawData!B48 / A34, RawData!B47))))) -> 828.47498
A35: 1.8946457e-05 | B35: =((RawData!B36-RawData!B37)*(RawData!B39+A35+RawData!B38-SQRT(POWER(RawData!B39+A35+RawData!B38,2)-(4*RawData!B39*A35)))/(2*RawData!B39))+RawData!B37 -> 822.26215 | C35: =RawData!B46 + ((RawData!B45 - RawData!B46) * (1 / (1 + (POWER(RawData!B48 / A35, RawData!B47))))) -> 828.36558
A36: 1.767767e-05 | B36: =((RawData!B36-RawData!B37)*(RawData!B39+A36+RawData!B38-SQRT(POWER(RawData!B39+A36+RawData!B38,2)-(4*RawData!B39*A36)))/(2*RawData!B39))+RawData!B37 -> 821.7386 | C36: =RawData!B46 + ((RawData!B45 - RawData!B46) * (1 / (1 + (POWER(RawData!B48 / A36, RawData!B47))))) -> 828.21987
A37: 1.6493849e-05 | B37: =((RawData!B36-RawData!B37)*(RawData!B39+A37+RawData!B38-SQRT(POWER(RawData!B39+A37+RawData!B38,2)-(4*RawData!B39*A37)))/(2*RawData!B39))+RawData!B37 -> 821.20118 | C37: =RawData!B46 + ((RawData!B45 - RawData!B46) * (1 / (1 + (POWER(RawData!B48 / A37, RawData!B47))))) -> 828.02635
A38: 1.5389305e-05 | B38: =((RawData!B36-RawData!B37)*(RawData!B39+A38+RawData!B38-SQRT(POWER(RawData!B39+A38+RawData!B38,2)-(4*RawData!B39*A38)))/(2*RawData!B39))+RawData!B37 -> 820.65067 | C38: =RawData!B46 + ((RawData!B45 - RawData!B46) * (1 / (1 + (POWER(RawData!B48 / A38, RawData!B47))))) -> 827.77032
A39: 1.435873e-05 | B39: =((RawData!B36-RawData!B37)*(RawData!B39+A39+RawData!B38-SQRT(POWER(RawData!B39+A39+RawData!B38,2)-(4*RawData!B39*A39)))/(2*RawData!B39))+RawData!B37 -> 820.08797 | C39: =RawData!B46 + ((RawData!B45 - RawData!B46) * (1 / (1 + (POWER(RawData!B48 / A39, RawData!B47))))) -> 827.43331
A40: 1.3397168e-05 | B40: =((RawData!B36-RawData!B37)*(RawData!B39+A40+RawData!B38-SQRT(POWER(RawData!B39+A40+RawData!B38,2)-(4*RawData!B39*A40)))/(2*RawData!B39))+RawData!B37 -> 819.51407 | C40: =RawData!B46 + ((RawData!B45 - RawData!B46) * (1 / (1 + (POWER(RawData!B48 / A40, RawData!B47))))) -> 826.99267
...
