Workbook

Sheet RawData
A1: NanoTemper Technologies | B1: NanoTemper Technologies
A2: MO.Affinity Analysis v2.3 | B2: MO.Affinity Analysis v2.3
A4: Origin of exported data | B4: Origin of exported data
A5: Project Title:
A6: Comment:
A7: Project File Path:
A8: Analysis-Set Name: | B8: Analysis-Set #17
A9: Exported from: | B9: Dose-Response (Grouped)
A10: Exported on: | B10: 45661.593
A12: Analysis Settings | B12: Analysis Settings
A13: Type of Analysis: | B13: MST
A14: Evaluation strategy: | B14: On Time
A15: Cold Region Start: | B15: -1
A16: Cold Region End: | B16: 0
A17: Hot Region Start: | B17: 4
A18: Hot Region End: | B18: 5
A20: Sample Information | B20: Sample Information | E20: Sample Information | F20: Sample Information | I20: Sample Information | J20: Sample Information
A21: Merge-Set Name: | B21: Experiment 1 (#01) | E21: Merge-Set Name: | F21: Experiment 2 (#02) | I21: Merge-Set Name: | J21: Experiment 3 (#03)
A22: Date of Measurement: | B22: 2025-01-03 08:39:48.116 → 2025-01-03 08:49:56.091 | E22: Date of Measurement: | F22: 2025-01-03 09:04:26.189 → 2025-01-03 09:14:34.266 | I22: Date of Measurement: | J22: 2025-01-03 09:28:35.7 → 2025-01-03 09:38:43.612
A23: Capillary Type: | B23: Unspecified container/capillary type | E23: Capillary Type: | F23: Unspecified container/capillary type | I23: Capillary Type: | J23: Unspecified container/capillary type
A24: Target: | B24: CD1d | E24: Target: | F24: CD1d | I24: Target: | J24: CD1d
A25: TargetConcentration: | B25: 1e-07 | E25: TargetConcentration: | F25: 1e-07 | I25: TargetConcentration: | J25: 1e-07
A26: Ligand: | B26: Tyloxapol | E26: Ligand: | F26: Tyloxapol | I26: Ligand: | J26: Tyloxapol
A28: Measurement Settings | B28: Measurement Settings | E28: Measurement Settings | F28: Measurement Settings | I28: Measurement Settings | J28: Measurement Settings
A29: MST-Power: | B29: Medium | E29: MST-Power: | F29: Medium | I29: MST-Power: | J29: Medium
A30: Excitation-Power: | B30: 30 | E30: Excitation-Power: | F30: 30 | I30: Excitation-Power: | J30: 30
A31: Excitation type: | B31: Nano - RED | E31: Excitation type: | F31: Nano - RED | I31: Excitation type: | J31: Nano - RED
A32: Thermostat Setpoint: | B32: 25 | E32: Thermostat Setpoint: | F32: 25 | I32: Thermostat Setpoint: | J32: 25
A34: Fit Results (Kd) | B34: Fit Results (Kd) | E34: Fit Results (Kd) | F34: Fit Results (Kd) | I34: Fit Results (Kd) | J34: Fit Results (Kd)
A35: Fit Model: | B35: Kd | E35: Fit Model: | F35: Kd | I35: Fit Model: | J35: Kd
A36: Bound | B36: 803.99853 | E36: Bound | F36: 808.46214 | I36: Bound | J36: 809.82308
A37: Unbound | B37: 788.24069 | E37: Unbound | F37: 788.63101 | I37: Unbound | J37: 790.69095
A38: Kd | B38: 1.0203015e-06 | E38: Kd | F38: 6.9472265e-07 | I38: Kd | J38: 6.5508543e-07
A39: TargetConc | B39: 1e-07 | E39: TargetConc | F39: 1e-07 | I39: TargetConc | J39: 1e-07
A40: Standard Deviation: | B40: 1.3577563 | E40: Standard Deviation: | F40: 1.3980065 | I40: Standard Deviation: | J40: 1.8579443
A41: Kd Confidence: | B41: 2.8505832e-07 | E41: Kd Confidence: | F41: 1.6536087e-07 | I41: Kd Confidence: | J41: 2.1631118e-07
A43: Dose Response Curve | B43: Dose Response Curve | C43: Dose Response Curve | E43: Dose Response Curve | F43: Dose Response Curve | G43: Dose Response Curve | I43: Dose Response Curve | J43: Dose Response Curve | K43: Dose Response Curve
A44: Ligand Concentration [M] | B44: Fnorm [‰] | C44: Error Value | E44: Ligand Concentration [M] | F44: Fnorm [‰] | G44: Error Value | I44: Ligand Concentration [M] | J44: Fnorm [‰] | K44: Error Value
A45: 0.001 | B45: 804.92814 | C45: 0 | E45: 0.001 | F45: 807.69035 | G45: 0 | I45: 0.001 | J45: 809.09303 | K45: 0
A46: 0.0005 | B46: 803.23628 | C46: 0 | E46: 0.0005 | F46: 807.22552 | G46: 0 | I46: 0.0005 | J46: 808.71865 | K46: 0
...

Sheet Graph

Sheet Fit-Values
A1: Dose | B1: FNorm | E1: Dose | F1: FNorm | I1: Dose | J1: FNorm
A2: 0.00093303299 | B2: =((RawData!B36-RawData!B37)*(RawData!B39+A2+RawData!B38-SQRT(POWER(RawData!B39+A2+RawData!B38,2)-(4*RawData!B39*A2)))/(2*RawData!B39))+RawData!B37 | E2: 0.00093303299 | F2: =((RawData!F36-RawData!F37)*(RawData!F39+E2+RawData!F38-SQRT(POWER(RawData!F39+E2+RawData!F38,2)-(4*RawData!F39*E2)))/(2*RawData!F39))+RawData!F37 | I2: 0.00093303299 | J2: =((RawData!J36-RawData!J37)*(RawData!J39+I2+RawData!J38-SQRT(POWER(RawData!J39+I2+RawData!J38,2)-(4*RawData!J39*I2)))/(2*RawData!J39))+RawData!J37
A3: 0.00087055056 | B3: =((RawData!B36-RawData!B37)*(RawData!B39+A3+RawData!B38-SQRT(POWER(RawData!B39+A3+RawData!B38,2)-(4*RawData!B39*A3)))/(2*RawData!B39))+RawData!B37 | E3: 0.00087055056 | F3: =((RawData!F36-RawData!F37)*(RawData!F39+E3+RawData!F38-SQRT(POWER(RawData!F39+E3+RawData!F38,2)-(4*RawData!F39*E3)))/(2*RawData!F39))+RawData!F37 | I3: 0.00087055056 | J3: =((RawData!J36-RawData!J37)*(RawData!J39+I3+RawData!J38-SQRT(POWER(RawData!J39+I3+RawData!J38,2)-(4*RawData!J39*I3)))/(2*RawData!J39))+RawData!J37
A4: 0.0008122524 | B4: =((RawData!B36-RawData!B37)*(RawData!B39+A4+RawData!B38-SQRT(POWER(RawData!B39+A4+RawData!B38,2)-(4*RawData!B39*A4)))/(2*RawData!B39))+RawData!B37 | E4: 0.0008122524 | F4: =((RawData!F36-RawData!F37)*(RawData!F39+E4+RawData!F38-SQRT(POWER(RawData!F39+E4+RawData!F38,2)-(4*RawData!F39*E4)))/(2*RawData!F39))+RawData!F37 | I4: 0.0008122524 | J4: =((RawData!J36-RawData!J37)*(RawData!J39+I4+RawData!J38-SQRT(POWER(RawData!J39+I4+RawData!J38,2)-(4*RawData!J39*I4)))/(2*RawData!J39))+RawData!J37
A5: 0.00075785828 | B5: =((RawData!B36-RawData!B37)*(RawData!B39+A5+RawData!B38-SQRT(POWER(RawData!B39+A5+RawData!B38,2)-(4*RawData!B39*A5)))/(2*RawData!B39))+RawData!B37 | E5: 0.00075785828 | F5: =((RawData!F36-RawData!F37)*(RawData!F39+E5+RawData!F38-SQRT(POWER(RawData!F39+E5+RawData!F38,2)-(4*RawData!F39*E5)))/(2*RawData!F39))+RawData!F37 | I5: 0.00075785828 | J5: =((RawData!J36-RawData!J37)*(RawData!J39+I5+RawData!J38-SQRT(POWER(RawData!J39+I5+RawData!J38,2)-(4*RawData!J39*I5)))/(2*RawData!J39))+RawData!J37
A6: 0.00070710678 | B6: =((RawData!B36-RawData!B37)*(RawData!B39+A6+RawData!B38-SQRT(POWER(RawData!B39+A6+RawData!B38,2)-(4*RawData!B39*A6)))/(2*RawData!B39))+RawData!B37 | E6: 0.00070710678 | F6: =((RawData!F36-RawData!F37)*(RawData!F39+E6+RawData!F38-SQRT(POWER(RawData!F39+E6+RawData!F38,2)-(4*RawData!F39*E6)))/(2*RawData!F39))+RawData!F37 | I6: 0.00070710678 | J6: =((RawData!J36-RawData!J37)*(RawData!J39+I6+RawData!J38-SQRT(POWER(RawData!J39+I6+RawData!J38,2)-(4*RawData!J39*I6)))/(2*RawData!J39))+RawData!J37
A7: 0.00065975396 | B7: =((RawData!B36-RawData!B37)*(RawData!B39+A7+RawData!B38-SQRT(POWER(RawData!B39+A7+RawData!B38,2)-(4*RawData!B39*A7)))/(2*RawData!B39))+RawData!B37 | E7: 0.00065975396 | F7: =((RawData!F36-RawData!F37)*(RawData!F39+E7+RawData!F38-SQRT(POWER(RawData!F39+E7+RawData!F38,2)-(4*RawData!F39*E7)))/(2*RawData!F39))+RawData!F37 | I7: 0.00065975396 | J7: =((RawData!J36-RawData!J37)*(RawData!J39+I7+RawData!J38-SQRT(POWER(RawData!J39+I7+RawData!J38,2)-(4*RawData!J39*I7)))/(2*RawData!J39))+RawData!J37
A8: 0.00061557221 | B8: =((RawData!B36-RawData!B37)*(RawData!B39+A8+RawData!B38-SQRT(POWER(RawData!B39+A8+RawData!B38,2)-(4*RawData!B39*A8)))/(2*RawData!B39))+RawData!B37 | E8: 0.00061557221 | F8: =((RawData!F36-RawData!F37)*(RawData!F39+E8+RawData!F38-SQRT(POWER(RawData!F39+E8+RawData!F38,2)-(4*RawData!F39*E8)))/(2*RawData!F39))+RawData!F37 | I8: 0.00061557221 | J8: =((RawData!J36-RawData!J37)*(RawData!J39+I8+RawData!J38-SQRT(POWER(RawData!J39+I8+RawData!J38,2)-(4*RawData!J39*I8)))/(2*RawData!J39))+RawData!J37
A9: 0.00057434918 | B9: =((RawData!B36-RawData!B37)*(RawData!B39+A9+RawData!B38-SQRT(POWER(RawData!B39+A9+RawData!B38,2)-(4*RawData!B39*A9)))/(2*RawData!B39))+RawData!B37 | E9: 0.00057434918 | F9: =((RawData!F36-RawData!F37)*(RawData!F39+E9+RawData!F38-SQRT(POWER(RawData!F39+E9+RawData!F38,2)-(4*RawData!F39*E9)))/(2*RawData!F39))+RawData!F37 | I9: 0.00057434918 | J9: =((RawData!J36-RawData!J37)*(RawData!J39+I9+RawData!J38-SQRT(POWER(RawData!J39+I9+RawData!J38,2)-(4*RawData!J39*I9)))/(2*RawData!J39))+RawData!J37
A10: 0.00053588673 | B10: =((RawData!B36-RawData!B37)*(RawData!B39+A10+RawData!B38-SQRT(POWER(RawData!B39+A10+RawData!B38,2)-(4*RawData!B39*A10)))/(2*RawData!B39))+RawData!B37 | E10: 0.00053588673 | F10: =((RawData!F36-RawData!F37)*(RawData!F39+E10+RawData!F38-SQRT(POWER(RawData!F39+E10+RawData!F38,2)-(4*RawData!F39*E10)))/(2*RawData!F39))+RawData!F37 | I10: 0.00053588673 | J10: =((RawData!J36-RawData!J37)*(RawData!J39+I10+RawData!J38-SQRT(POWER(RawData!J39+I10+RawData!J38,2)-(4*RawData!J39*I10)))/(2*RawData!J39))+RawData!J37
A11: 0.0005 | B11: =((RawData!B36-RawData!B37)*(RawData!B39+A11+RawData!B38-SQRT(POWER(RawData!B39+A11+RawData!B38,2)-(4*RawData!B39*A11)))/(2*RawData!B39))+RawData!B37 | E11: 0.0005 | F11: =((RawData!F36-RawData!F37)*(RawData!F39+E11+RawData!F38-SQRT(POWER(RawData!F39+E11+RawData!F38,2)-(4*RawData!F39*E11)))/(2*RawData!F39))+RawData!F37 | I11: 0.0005 | J11: =((RawData!J36-RawData!J37)*(RawData!J39+I11+RawData!J38-SQRT(POWER(RawData!J39+I11+RawData!J38,2)-(4*RawData!J39*I11)))/(2*RawData!J39))+RawData!J37
A12: 0.0004665165 | B12: =((RawData!B36-RawData!B37)*(RawData!B39+A12+RawData!B38-SQRT(POWER(RawData!B39+A12+RawData!B38,2)-(4*RawData!B39*A12)))/(2*RawData!B39))+RawData!B37 | E12: 0.0004665165 | F12: =((RawData!F36-RawData!F37)*(RawData!F39+E12+RawData!F38-SQRT(POWER(RawData!F39+E12+RawData!F38,2)-(4*RawData!F39*E12)))/(2*RawData!F39))+RawData!F37 | I12: 0.0004665165 | J12: =((RawData!J36-RawData!J37)*(RawData!J39+I12+RawData!J38-SQRT(POWER(RawData!J39+I12+RawData!J38,2)-(4*RawData!J39*I12)))/(2*RawData!J39))+RawData!J37
A13: 0.00043527528 | B13: =((RawData!B36-RawData!B37)*(RawData!B39+A13+RawData!B38-SQRT(POWER(RawData!B39+A13+RawData!B38,2)-(4*RawData!B39*A13)))/(2*RawData!B39))+RawData!B37 | E13: 0.00043527528 | F13: =((RawData!F36-RawData!F37)*(RawData!F39+E13+RawData!F38-SQRT(POWER(RawData!F39+E13+RawData!F38,2)-(4*RawData!F39*E13)))/(2*RawData!F39))+RawData!F37 | I13: 0.00043527528 | J13: =((RawData!J36-RawData!J37)*(RawData!J39+I13+RawData!J38-SQRT(POWER(RawData!J39+I13+RawData!J38,2)-(4*RawData!J39*I13)))/(2*RawData!J39))+RawData!J37
A14: 0.0004061262 | B14: =((RawData!B36-RawData!B37)*(RawData!B39+A14+RawData!B38-SQRT(POWER(RawData!B39+A14+RawData!B38,2)-(4*RawData!B39*A14)))/(2*RawData!B39))+RawData!B37 | E14: 0.0004061262 | F14: =((RawData!F36-RawData!F37)*(RawData!F39+E14+RawData!F38-SQRT(POWER(RawData!F39+E14+RawData!F38,2)-(4*RawData!F39*E14)))/(2*RawData!F39))+RawData!F37 | I14: 0.0004061262 | J14: =((RawData!J36-RawData!J37)*(RawData!J39+I14+RawData!J38-SQRT(POWER(RawData!J39+I14+RawData!J38,2)-(4*RawData!J39*I14)))/(2*RawData!J39))+RawData!J37
A15: 0.00037892914 | B15: =((RawData!B36-RawData!B37)*(RawData!B39+A15+RawData!B38-SQRT(POWER(RawData!B39+A15+RawData!B38,2)-(4*RawData!B39*A15)))/(2*RawData!B39))+RawData!B37 | E15: 0.00037892914 | F15: =((RawData!F36-RawData!F37)*(RawData!F39+E15+RawData!F38-SQRT(POWER(RawData!F39+E15+RawData!F38,2)-(4*RawData!F39*E15)))/(2*RawData!F39))+RawData!F37 | I15: 0.00037892914 | J15: =((RawData!J36-RawData!J37)*(RawData!J39+I15+RawData!J38-SQRT(POWER(RawData!J39+I15+RawData!J38,2)-(4*RawData!J39*I15)))/(2*RawData!J39))+RawData!J37
A16: 0.00035355339 | B16: =((RawData!B36-RawData!B37)*(RawData!B39+A16+RawData!B38-SQRT(POWER(RawData!B39+A16+RawData!B38,2)-(4*RawData!B39*A16)))/(2*RawData!B39))+RawData!B37 | E16: 0.00035355339 | F16: =((RawData!F36-RawData!F37)*(RawData!F39+E16+RawData!F38-SQRT(POWER(RawData!F39+E16+RawData!F38,2)-(4*RawData!F39*E16)))/(2*RawData!F39))+RawData!F37 | I16: 0.00035355339 | J16: =((RawData!J36-RawData!J37)*(RawData!J39+I16+RawData!J38-SQRT(POWER(RawData!J39+I16+RawData!J38,2)-(4*RawData!J39*I16)))/(2*RawData!J39))+RawData!J37
A17: 0.00032987698 | B17: =((RawData!B36-RawData!B37)*(RawData!B39+A17+RawData!B38-SQRT(POWER(RawData!B39+A17+RawData!B38,2)-(4*RawData!B39*A17)))/(2*RawData!B39))+RawData!B37 | E17: 0.00032987698 | F17: =((RawData!F36-RawData!F37)*(RawData!F39+E17+RawData!F38-SQRT(POWER(RawData!F39+E17+RawData!F38,2)-(4*RawData!F39*E17)))/(2*RawData!F39))+RawData!F37 | I17: 0.00032987698 | J17: =((RawData!J36-RawData!J37)*(RawData!J39+I17+RawData!J38-SQRT(POWER(RawData!J39+I17+RawData!J38,2)-(4*RawData!J39*I17)))/(2*RawData!J39))+RawData!J37
A18: 0.0003077861 | B18: =((RawData!B36-RawData!B37)*(RawData!B39+A18+RawData!B38-SQRT(POWER(RawData!B39+A18+RawData!B38,2)-(4*RawData!B39*A18)))/(2*RawData!B39))+RawData!B37 | E18: 0.0003077861 | F18: =((RawData!F36-RawData!F37)*(RawData!F39+E18+RawData!F38-SQRT(POWER(RawData!F39+E18+RawData!F38,2)-(4*RawData!F39*E18)))/(2*RawData!F39))+RawData!F37 | I18: 0.0003077861 | J18: =((RawData!J36-RawData!J37)*(RawData!J39+I18+RawData!J38-SQRT(POWER(RawData!J39+I18+RawData!J38,2)-(4*RawData!J39*I18)))/(2*RawData!J39))+RawData!J37
A19: 0.00028717459 | B19: =((RawData!B36-RawData!B37)*(RawData!B39+A19+RawData!B38-SQRT(POWER(RawData!B39+A19+RawData!B38,2)-(4*RawData!B39*A19)))/(2*RawData!B39))+RawData!B37 | E19: 0.00028717459 | F19: =((RawData!F36-RawData!F37)*(RawData!F39+E19+RawData!F38-SQRT(POWER(RawData!F39+E19+RawData!F38,2)-(4*RawData!F39*E19)))/(2*RawData!F39))+RawData!F37 | I19: 0.00028717459 | J19: =((RawData!J36-RawData!J37)*(RawData!J39+I19+RawData!J38-SQRT(POWER(RawData!J39+I19+RawData!J38,2)-(4*RawData!J39*I19)))/(2*RawData!J39))+RawData!J37
A20: 0.00026794337 | B20: =((RawData!B36-RawData!B37)*(RawData!B39+A20+RawData!B38-SQRT(POWER(RawData!B39+A20+RawData!B38,2)-(4*RawData!B39*A20)))/(2*RawData!B39))+RawData!B37 | E20: 0.00026794337 | F20: =((RawData!F36-RawData!F37)*(RawData!F39+E20+RawData!F38-SQRT(POWER(RawData!F39+E20+RawData!F38,2)-(4*RawData!F39*E20)))/(2*RawData!F39))+RawData!F37 | I20: 0.00026794337 | J20: =((RawData!J36-RawData!J37)*(RawData!J39+I20+RawData!J38-SQRT(POWER(RawData!J39+I20+RawData!J38,2)-(4*RawData!J39*I20)))/(2*RawData!J39))+RawData!J37
A21: 0.00025 | B21: =((RawData!B36-RawData!B37)*(RawData!B39+A21+RawData!B38-SQRT(POWER(RawData!B39+A21+RawData!B38,2)-(4*RawData!B39*A21)))/(2*RawData!B39))+RawData!B37 | E21: 0.00025 | F21: =((RawData!F36-RawData!F37)*(RawData!F39+E21+RawData!F38-SQRT(POWER(RawData!F39+E21+RawData!F38,2)-(4*RawData!F39*E21)))/(2*RawData!F39))+RawData!F37 | I21: 0.00025 | J21: =((RawData!J36-RawData!J37)*(RawData!J39+I21+RawData!J38-SQRT(POWER(RawData!J39+I21+RawData!J38,2)-(4*RawData!J39*I21)))/(2*RawData!J39))+RawData!J37
A22: 0.00023325825 | B22: =((RawData!B36-RawData!B37)*(RawData!B39+A22+RawData!B38-SQRT(POWER(RawData!B39+A22+RawData!B38,2)-(4*RawData!B39*A22)))/(2*RawData!B39))+RawData!B37 | E22: 0.00023325825 | F22: =((RawData!F36-RawData!F37)*(RawData!F39+E22+RawData!F38-SQRT(POWER(RawData!F39+E22+RawData!F38,2)-(4*RawData!F39*E22)))/(2*RawData!F39))+RawData!F37 | I22: 0.00023325825 | J22: =((RawData!J36-RawData!J37)*(RawData!J39+I22+RawData!J38-SQRT(POWER(RawData!J39+I22+RawData!J38,2)-(4*RawData!J39*I22)))/(2*RawData!J39))+RawData!J37
A23: 0.00021763764 | B23: =((RawData!B36-RawData!B37)*(RawData!B39+A23+RawData!B38-SQRT(POWER(RawData!B39+A23+RawData!B38,2)-(4*RawData!B39*A23)))/(2*RawData!B39))+RawData!B37 | E23: 0.00021763764 | F23: =((RawData!F36-RawData!F37)*(RawData!F39+E23+RawData!F38-SQRT(POWER(RawData!F39+E23+RawData!F38,2)-(4*RawData!F39*E23)))/(2*RawData!F39))+RawData!F37 | I23: 0.00021763764 | J23: =((RawData!J36-RawData!J37)*(RawData!J39+I23+RawData!J38-SQRT(POWER(RawData!J39+I23+RawData!J38,2)-(4*RawData!J39*I23)))/(2*RawData!J39))+RawData!J37
A24: 0.0002030631 | B24: =((RawData!B36-RawData!B37)*(RawData!B39+A24+RawData!B38-SQRT(POWER(RawData!B39+A24+RawData!B38,2)-(4*RawData!B39*A24)))/(2*RawData!B39))+RawData!B37 | E24: 0.0002030631 | F24: =((RawData!F36-RawData!F37)*(RawData!F39+E24+RawData!F38-SQRT(POWER(RawData!F39+E24+RawData!F38,2)-(4*RawData!F39*E24)))/(2*RawData!F39))+RawData!F37 | I24: 0.0002030631 | J24: =((RawData!J36-RawData!J37)*(RawData!J39+I24+RawData!J38-SQRT(POWER(RawData!J39+I24+RawData!J38,2)-(4*RawData!J39*I24)))/(2*RawData!J39))+RawData!J37
A25: 0.00018946457 | B25: =((RawData!B36-RawData!B37)*(RawData!B39+A25+RawData!B38-SQRT(POWER(RawData!B39+A25+RawData!B38,2)-(4*RawData!B39*A25)))/(2*RawData!B39))+RawData!B37 | E25: 0.00018946457 | F25: =((RawData!F36-RawData!F37)*(RawData!F39+E25+RawData!F38-SQRT(POWER(RawData!F39+E25+RawData!F38,2)-(4*RawData!F39*E25)))/(2*RawData!F39))+RawData!F37 | I25: 0.00018946457 | J25: =((RawData!J36-RawData!J37)*(RawData!J39+I25+RawData!J38-SQRT(POWER(RawData!J39+I25+RawData!J38,2)-(4*RawData!J39*I25)))/(2*RawData!J39))+RawData!J37
A26: 0.0001767767 | B26: =((RawData!B36-RawData!B37)*(RawData!B39+A26+RawData!B38-SQRT(POWER(RawData!B39+A26+RawData!B38,2)-(4*RawData!B39*A26)))/(2*RawData!B39))+RawData!B37 | E26: 0.0001767767 | F26: =((RawData!F36-RawData!F37)*(RawData!F39+E26+RawData!F38-SQRT(POWER(RawData!F39+E26+RawData!F38,2)-(4*RawData!F39*E26)))/(2*RawData!F39))+RawData!F37 | I26: 0.0001767767 | J26: =((RawData!J36-RawData!J37)*(RawData!J39+I26+RawData!J38-SQRT(POWER(RawData!J39+I26+RawData!J38,2)-(4*RawData!J39*I26)))/(2*RawData!J39))+RawData!J37
A27: 0.00016493849 | B27: =((RawData!B36-RawData!B37)*(RawData!B39+A27+RawData!B38-SQRT(POWER(RawData!B39+A27+RawData!B38,2)-(4*RawData!B39*A27)))/(2*RawData!B39))+RawData!B37 | E27: 0.00016493849 | F27: =((RawData!F36-RawData!F37)*(RawData!F39+E27+RawData!F38-SQRT(POWER(RawData!F39+E27+RawData!F38,2)-(4*RawData!F39*E27)))/(2*RawData!F39))+RawData!F37 | I27: 0.00016493849 | J27: =((RawData!J36-RawData!J37)*(RawData!J39+I27+RawData!J38-SQRT(POWER(RawData!J39+I27+RawData!J38,2)-(4*RawData!J39*I27)))/(2*RawData!J39))+RawData!J37
A28: 0.00015389305 | B28: =((RawData!B36-RawData!B37)*(RawData!B39+A28+RawData!B38-SQRT(POWER(RawData!B39+A28+RawData!B38,2)-(4*RawData!B39*A28)))/(2*RawData!B39))+RawData!B37 | E28: 0.00015389305 | F28: =((RawData!F36-RawData!F37)*(RawData!F39+E28+RawData!F38-SQRT(POWER(RawData!F39+E28+RawData!F38,2)-(4*RawData!F39*E28)))/(2*RawData!F39))+RawData!F37 | I28: 0.00015389305 | J28: =((RawData!J36-RawData!J37)*(RawData!J39+I28+RawData!J38-SQRT(POWER(RawData!J39+I28+RawData!J38,2)-(4*RawData!J39*I28)))/(2*RawData!J39))+RawData!J37
A29: 0.00014358729 | B29: =((RawData!B36-RawData!B37)*(RawData!B39+A29+RawData!B38-SQRT(POWER(RawData!B39+A29+RawData!B38,2)-(4*RawData!B39*A29)))/(2*RawData!B39))+RawData!B37 | E29: 0.00014358729 | F29: =((RawData!F36-RawData!F37)*(RawData!F39+E29+RawData!F38-SQRT(POWER(RawData!F39+E29+RawData!F38,2)-(4*RawData!F39*E29)))/(2*RawData!F39))+RawData!F37 | I29: 0.00014358729 | J29: =((RawData!J36-RawData!J37)*(RawData!J39+I29+RawData!J38-SQRT(POWER(RawData!J39+I29+RawData!J38,2)-(4*RawData!J39*I29)))/(2*RawData!J39))+RawData!J37
A30: 0.00013397168 | B30: =((RawData!B36-RawData!B37)*(RawData!B39+A30+RawData!B38-SQRT(POWER(RawData!B39+A30+RawData!B38,2)-(4*RawData!B39*A30)))/(2*RawData!B39))+RawData!B37 | E30: 0.00013397168 | F30: =((RawData!F36-RawData!F37)*(RawData!F39+E30+RawData!F38-SQRT(POWER(RawData!F39+E30+RawData!F38,2)-(4*RawData!F39*E30)))/(2*RawData!F39))+RawData!F37 | I30: 0.00013397168 | J30: =((RawData!J36-RawData!J37)*(RawData!J39+I30+RawData!J38-SQRT(POWER(RawData!J39+I30+RawData!J38,2)-(4*RawData!J39*I30)))/(2*RawData!J39))+RawData!J37
A31: 0.000125 | B31: =((RawData!B36-RawData!B37)*(RawData!B39+A31+RawData!B38-SQRT(POWER(RawData!B39+A31+RawData!B38,2)-(4*RawData!B39*A31)))/(2*RawData!B39))+RawData!B37 | E31: 0.000125 | F31: =((RawData!F36-RawData!F37)*(RawData!F39+E31+RawData!F38-SQRT(POWER(RawData!F39+E31+RawData!F38,2)-(4*RawData!F39*E31)))/(2*RawData!F39))+RawData!F37 | I31: 0.000125 | J31: =((RawData!J36-RawData!J37)*(RawData!J39+I31+RawData!J38-SQRT(POWER(RawData!J39+I31+RawData!J38,2)-(4*RawData!J39*I31)))/(2*RawData!J39))+RawData!J37
A32: 0.00011662912 | B32: =((RawData!B36-RawData!B37)*(RawData!B39+A32+RawData!B38-SQRT(POWER(RawData!B39+A32+RawData!B38,2)-(4*RawData!B39*A32)))/(2*RawData!B39))+RawData!B37 | E32: 0.00011662912 | F32: =((RawData!F36-RawData!F37)*(RawData!F39+E32+RawData!F38-SQRT(POWER(RawData!F39+E32+RawData!F38,2)-(4*RawData!F39*E32)))/(2*RawData!F39))+RawData!F37 | I32: 0.00011662912 | J32: =((RawData!J36-RawData!J37)*(RawData!J39+I32+RawData!J38-SQRT(POWER(RawData!J39+I32+RawData!J38,2)-(4*RawData!J39*I32)))/(2*RawData!J39))+RawData!J37
A33: 0.00010881882 | B33: =((RawData!B36-RawData!B37)*(RawData!B39+A33+RawData!B38-SQRT(POWER(RawData!B39+A33+RawData!B38,2)-(4*RawData!B39*A33)))/(2*RawData!B39))+RawData!B37 | E33: 0.00010881882 | F33: =((RawData!F36-RawData!F37)*(RawData!F39+E33+RawData!F38-SQRT(POWER(RawData!F39+E33+RawData!F38,2)-(4*RawData!F39*E33)))/(2*RawData!F39))+RawData!F37 | I33: 0.00010881882 | J33: =((RawData!J36-RawData!J37)*(RawData!J39+I33+RawData!J38-SQRT(POWER(RawData!J39+I33+RawData!J38,2)-(4*RawData!J39*I33)))/(2*RawData!J39))+RawData!J37
A34: 0.00010153155 | B34: =((RawData!B36-RawData!B37)*(RawData!B39+A34+RawData!B38-SQRT(POWER(RawData!B39+A34+RawData!B38,2)-(4*RawData!B39*A34)))/(2*RawData!B39))+RawData!B37 | E34: 0.00010153155 | F34: =((RawData!F36-RawData!F37)*(RawData!F39+E34+RawData!F38-SQRT(POWER(RawData!F39+E34+RawData!F38,2)-(4*RawData!F39*E34)))/(2*RawData!F39))+RawData!F37 | I34: 0.00010153155 | J34: =((RawData!J36-RawData!J37)*(RawData!J39+I34+RawData!J38-SQRT(POWER(RawData!J39+I34+RawData!J38,2)-(4*RawData!J39*I34)))/(2*RawData!J39))+RawData!J37
A35: 9.4732285e-05 | B35: =((RawData!B36-RawData!B37)*(RawData!B39+A35+RawData!B38-SQRT(POWER(RawData!B39+A35+RawData!B38,2)-(4*RawData!B39*A35)))/(2*RawData!B39))+RawData!B37 | E35: 9.4732285e-05 | F35: =((RawData!F36-RawData!F37)*(RawData!F39+E35+RawData!F38-SQRT(POWER(RawData!F39+E35+RawData!F38,2)-(4*RawData!F39*E35)))/(2*RawData!F39))+RawData!F37 | I35: 9.4732285e-05 | J35: =((RawData!J36-RawData!J37)*(RawData!J39+I35+RawData!J38-SQRT(POWER(RawData!J39+I35+RawData!J38,2)-(4*RawData!J39*I35)))/(2*RawData!J39))+RawData!J37
A36: 8.8388348e-05 | B36: =((RawData!B36-RawData!B37)*(RawData!B39+A36+RawData!B38-SQRT(POWER(RawData!B39+A36+RawData!B38,2)-(4*RawData!B39*A36)))/(2*RawData!B39))+RawData!B37 | E36: 8.8388348e-05 | F36: =((RawData!F36-RawData!F37)*(RawData!F39+E36+RawData!F38-SQRT(POWER(RawData!F39+E36+RawData!F38,2)-(4*RawData!F39*E36)))/(2*RawData!F39))+RawData!F37 | I36: 8.8388348e-05 | J36: =((RawData!J36-RawData!J37)*(RawData!J39+I36+RawData!J38-SQRT(POWER(RawData!J39+I36+RawData!J38,2)-(4*RawData!J39*I36)))/(2*RawData!J39))+RawData!J37
A37: 8.2469244e-05 | B37: =((RawData!B36-RawData!B37)*(RawData!B39+A37+RawData!B38-SQRT(POWER(RawData!B39+A37+RawData!B38,2)-(4*RawData!B39*A37)))/(2*RawData!B39))+RawData!B37 | E37: 8.2469244e-05 | F37: =((RawData!F36-RawData!F37)*(RawData!F39+E37+RawData!F38-SQRT(POWER(RawData!F39+E37+RawData!F38,2)-(4*RawData!F39*E37)))/(2*RawData!F39))+RawData!F37 | I37: 8.2469244e-05 | J37: =((RawData!J36-RawData!J37)*(RawData!J39+I37+RawData!J38-SQRT(POWER(RawData!J39+I37+RawData!J38,2)-(4*RawData!J39*I37)))/(2*RawData!J39))+RawData!J37
A38: 7.6946526e-05 | B38: =((RawData!B36-RawData!B37)*(RawData!B39+A38+RawData!B38-SQRT(POWER(RawData!B39+A38+RawData!B38,2)-(4*RawData!B39*A38)))/(2*RawData!B39))+RawData!B37 | E38: 7.6946526e-05 | F38: =((RawData!F36-RawData!F37)*(RawData!F39+E38+RawData!F38-SQRT(POWER(RawData!F39+E38+RawData!F38,2)-(4*RawData!F39*E38)))/(2*RawData!F39))+RawData!F37 | I38: 7.6946526e-05 | J38: =((RawData!J36-RawData!J37)*(RawData!J39+I38+RawData!J38-SQRT(POWER(RawData!J39+I38+RawData!J38,2)-(4*RawData!J39*I38)))/(2*RawData!J39))+RawData!J37
A39: 7.1793647e-05 | B39: =((RawData!B36-RawData!B37)*(RawData!B39+A39+RawData!B38-SQRT(POWER(RawData!B39+A39+RawData!B38,2)-(4*RawData!B39*A39)))/(2*RawData!B39))+RawData!B37 | E39: 7.1793647e-05 | F39: =((RawData!F36-RawData!F37)*(RawData!F39+E39+RawData!F38-SQRT(POWER(RawData!F39+E39+RawData!F38,2)-(4*RawData!F39*E39)))/(2*RawData!F39))+RawData!F37 | I39: 7.1793647e-05 | J39: =((RawData!J36-RawData!J37)*(RawData!J39+I39+RawData!J38-SQRT(POWER(RawData!J39+I39+RawData!J38,2)-(4*RawData!J39*I39)))/(2*RawData!J39))+RawData!J37
A40: 6.6985841e-05 | B40: =((RawData!B36-RawData!B37)*(RawData!B39+A40+RawData!B38-SQRT(POWER(RawData!B39+A40+RawData!B38,2)-(4*RawData!B39*A40)))/(2*RawData!B39))+RawData!B37 | E40: 6.6985841e-05 | F40: =((RawData!F36-RawData!F37)*(RawData!F39+E40+RawData!F38-SQRT(POWER(RawData!F39+E40+RawData!F38,2)-(4*RawData!F39*E40)))/(2*RawData!F39))+RawData!F37 | I40: 6.6985841e-05 | J40: =((RawData!J36-RawData!J37)*(RawData!J39+I40+RawData!J38-SQRT(POWER(RawData!J39+I40+RawData!J38,2)-(4*RawData!J39*I40)))/(2*RawData!J39))+RawData!J37
...
